/usr/local/lib/python3.6/dist-packages/telegram/ext/conversationhandler.py:280: UserWarning: If 'per_message=False', 'CallbackQueryHandler' will not be tracked for every message.
  "If 'per_message=False', 'CallbackQueryHandler' will not be "
Error while getting Updates: Conflict: terminated by other getUpdates request; make sure that only one bot instance is running
An uncaught error was raised while handling the error.
Traceback (most recent call last):
  File "/usr/local/lib/python3.6/dist-packages/telegram/ext/dispatcher.py", line 424, in process_update
    self.dispatch_error(None, update)
  File "/usr/local/lib/python3.6/dist-packages/telegram/ext/dispatcher.py", line 674, in dispatch_error
    callback(update, context)
  File "/root/BlockchainBot/base.py", line 56, in error_handler
    url = f"https://api.telegram.org/bot{evars['bot_token']}/sendDocument?chat_id={evars['dev_chat_id']}"
  File "/usr/lib/python3.6/os.py", line 669, in __getitem__
    raise KeyError(key) from None
KeyError: 'dev_chat_id'
Error while getting Updates: Conflict: terminated by other getUpdates request; make sure that only one bot instance is running
An uncaught error was raised while handling the error.
Traceback (most recent call last):
  File "/usr/local/lib/python3.6/dist-packages/telegram/ext/dispatcher.py", line 424, in process_update
    self.dispatch_error(None, update)
  File "/usr/local/lib/python3.6/dist-packages/telegram/ext/dispatcher.py", line 674, in dispatch_error
    callback(update, context)
  File "/root/BlockchainBot/base.py", line 56, in error_handler
    url = f"https://api.telegram.org/bot{evars['bot_token']}/sendDocument?chat_id={evars['dev_chat_id']}"
  File "/usr/lib/python3.6/os.py", line 669, in __getitem__
    raise KeyError(key) from None
KeyError: 'dev_chat_id'
Error while getting Updates: Conflict: terminated by other getUpdates request; make sure that only one bot instance is running
An uncaught error was raised while handling the error.
Traceback (most recent call last):
  File "/usr/local/lib/python3.6/dist-packages/telegram/ext/dispatcher.py", line 424, in process_update
    self.dispatch_error(None, update)
  File "/usr/local/lib/python3.6/dist-packages/telegram/ext/dispatcher.py", line 674, in dispatch_error
    callback(update, context)
  File "/root/BlockchainBot/base.py", line 56, in error_handler
    url = f"https://api.telegram.org/bot{evars['bot_token']}/sendDocument?chat_id={evars['dev_chat_id']}"
  File "/usr/lib/python3.6/os.py", line 669, in __getitem__
    raise KeyError(key) from None
KeyError: 'dev_chat_id'
Error while getting Updates: Conflict: terminated by other getUpdates request; make sure that only one bot instance is running
An uncaught error was raised while handling the error.
Traceback (most recent call last):
  File "/usr/local/lib/python3.6/dist-packages/telegram/ext/dispatcher.py", line 424, in process_update
    self.dispatch_error(None, update)
  File "/usr/local/lib/python3.6/dist-packages/telegram/ext/dispatcher.py", line 674, in dispatch_error
    callback(update, context)
  File "/root/BlockchainBot/base.py", line 56, in error_handler
    url = f"https://api.telegram.org/bot{evars['bot_token']}/sendDocument?chat_id={evars['dev_chat_id']}"
  File "/usr/lib/python3.6/os.py", line 669, in __getitem__
    raise KeyError(key) from None
KeyError: 'dev_chat_id'
Error while getting Updates: Conflict: terminated by other getUpdates request; make sure that only one bot instance is running
An uncaught error was raised while handling the error.
Traceback (most recent call last):
  File "/usr/local/lib/python3.6/dist-packages/telegram/ext/dispatcher.py", line 424, in process_update
    self.dispatch_error(None, update)
  File "/usr/local/lib/python3.6/dist-packages/telegram/ext/dispatcher.py", line 674, in dispatch_error
    callback(update, context)
  File "/root/BlockchainBot/base.py", line 56, in error_handler
    url = f"https://api.telegram.org/bot{evars['bot_token']}/sendDocument?chat_id={evars['dev_chat_id']}"
  File "/usr/lib/python3.6/os.py", line 669, in __getitem__
    raise KeyError(key) from None
KeyError: 'dev_chat_id'
Error while getting Updates: Conflict: terminated by other getUpdates request; make sure that only one bot instance is running
An uncaught error was raised while handling the error.
Traceback (most recent call last):
  File "/usr/local/lib/python3.6/dist-packages/telegram/ext/dispatcher.py", line 424, in process_update
    self.dispatch_error(None, update)
  File "/usr/local/lib/python3.6/dist-packages/telegram/ext/dispatcher.py", line 674, in dispatch_error
    callback(update, context)
  File "/root/BlockchainBot/base.py", line 56, in error_handler
    url = f"https://api.telegram.org/bot{evars['bot_token']}/sendDocument?chat_id={evars['dev_chat_id']}"
  File "/usr/lib/python3.6/os.py", line 669, in __getitem__
    raise KeyError(key) from None
KeyError: 'dev_chat_id'
Error while getting Updates: Conflict: terminated by other getUpdates request; make sure that only one bot instance is running
An uncaught error was raised while handling the error.
Traceback (most recent call last):
  File "/usr/local/lib/python3.6/dist-packages/telegram/ext/dispatcher.py", line 424, in process_update
    self.dispatch_error(None, update)
  File "/usr/local/lib/python3.6/dist-packages/telegram/ext/dispatcher.py", line 674, in dispatch_error
    callback(update, context)
  File "/root/BlockchainBot/base.py", line 56, in error_handler
    url = f"https://api.telegram.org/bot{evars['bot_token']}/sendDocument?chat_id={evars['dev_chat_id']}"
  File "/usr/lib/python3.6/os.py", line 669, in __getitem__
    raise KeyError(key) from None
KeyError: 'dev_chat_id'
Error while getting Updates: Conflict: terminated by other getUpdates request; make sure that only one bot instance is running
An uncaught error was raised while handling the error.
Traceback (most recent call last):
  File "/usr/local/lib/python3.6/dist-packages/telegram/ext/dispatcher.py", line 424, in process_update
    self.dispatch_error(None, update)
  File "/usr/local/lib/python3.6/dist-packages/telegram/ext/dispatcher.py", line 674, in dispatch_error
    callback(update, context)
  File "/root/BlockchainBot/base.py", line 56, in error_handler
    url = f"https://api.telegram.org/bot{evars['bot_token']}/sendDocument?chat_id={evars['dev_chat_id']}"
  File "/usr/lib/python3.6/os.py", line 669, in __getitem__
    raise KeyError(key) from None
KeyError: 'dev_chat_id'
Error while getting Updates: Conflict: terminated by other getUpdates request; make sure that only one bot instance is running
An uncaught error was raised while handling the error.
Traceback (most recent call last):
  File "/usr/local/lib/python3.6/dist-packages/telegram/ext/dispatcher.py", line 424, in process_update
    self.dispatch_error(None, update)
  File "/usr/local/lib/python3.6/dist-packages/telegram/ext/dispatcher.py", line 674, in dispatch_error
    callback(update, context)
  File "/root/BlockchainBot/base.py", line 56, in error_handler
    url = f"https://api.telegram.org/bot{evars['bot_token']}/sendDocument?chat_id={evars['dev_chat_id']}"
  File "/usr/lib/python3.6/os.py", line 669, in __getitem__
    raise KeyError(key) from None
KeyError: 'dev_chat_id'
Error while getting Updates: Conflict: terminated by other getUpdates request; make sure that only one bot instance is running
An uncaught error was raised while handling the error.
Traceback (most recent call last):
  File "/usr/local/lib/python3.6/dist-packages/telegram/ext/dispatcher.py", line 424, in process_update
    self.dispatch_error(None, update)
  File "/usr/local/lib/python3.6/dist-packages/telegram/ext/dispatcher.py", line 674, in dispatch_error
    callback(update, context)
  File "/root/BlockchainBot/base.py", line 56, in error_handler
    url = f"https://api.telegram.org/bot{evars['bot_token']}/sendDocument?chat_id={evars['dev_chat_id']}"
  File "/usr/lib/python3.6/os.py", line 669, in __getitem__
    raise KeyError(key) from None
KeyError: 'dev_chat_id'
Error while getting Updates: Conflict: terminated by other getUpdates request; make sure that only one bot instance is running
An uncaught error was raised while handling the error.
Traceback (most recent call last):
  File "/usr/local/lib/python3.6/dist-packages/telegram/ext/dispatcher.py", line 424, in process_update
    self.dispatch_error(None, update)
  File "/usr/local/lib/python3.6/dist-packages/telegram/ext/dispatcher.py", line 674, in dispatch_error
    callback(update, context)
  File "/root/BlockchainBot/base.py", line 56, in error_handler
    url = f"https://api.telegram.org/bot{evars['bot_token']}/sendDocument?chat_id={evars['dev_chat_id']}"
  File "/usr/lib/python3.6/os.py", line 669, in __getitem__
    raise KeyError(key) from None
KeyError: 'dev_chat_id'
Error while getting Updates: Conflict: terminated by other getUpdates request; make sure that only one bot instance is running
An uncaught error was raised while handling the error.
Traceback (most recent call last):
  File "/usr/local/lib/python3.6/dist-packages/telegram/ext/dispatcher.py", line 424, in process_update
    self.dispatch_error(None, update)
  File "/usr/local/lib/python3.6/dist-packages/telegram/ext/dispatcher.py", line 674, in dispatch_error
    callback(update, context)
  File "/root/BlockchainBot/base.py", line 56, in error_handler
    url = f"https://api.telegram.org/bot{evars['bot_token']}/sendDocument?chat_id={evars['dev_chat_id']}"
  File "/usr/lib/python3.6/os.py", line 669, in __getitem__
    raise KeyError(key) from None
KeyError: 'dev_chat_id'
Error while getting Updates: Conflict: terminated by other getUpdates request; make sure that only one bot instance is running
An uncaught error was raised while handling the error.
Traceback (most recent call last):
  File "/usr/local/lib/python3.6/dist-packages/telegram/ext/dispatcher.py", line 424, in process_update
    self.dispatch_error(None, update)
  File "/usr/local/lib/python3.6/dist-packages/telegram/ext/dispatcher.py", line 674, in dispatch_error
    callback(update, context)
  File "/root/BlockchainBot/base.py", line 56, in error_handler
    url = f"https://api.telegram.org/bot{evars['bot_token']}/sendDocument?chat_id={evars['dev_chat_id']}"
  File "/usr/lib/python3.6/os.py", line 669, in __getitem__
    raise KeyError(key) from None
KeyError: 'dev_chat_id'
Error while getting Updates: Conflict: terminated by other getUpdates request; make sure that only one bot instance is running
An uncaught error was raised while handling the error.
Traceback (most recent call last):
  File "/usr/local/lib/python3.6/dist-packages/telegram/ext/dispatcher.py", line 424, in process_update
    self.dispatch_error(None, update)
  File "/usr/local/lib/python3.6/dist-packages/telegram/ext/dispatcher.py", line 674, in dispatch_error
    callback(update, context)
  File "/root/BlockchainBot/base.py", line 56, in error_handler
    url = f"https://api.telegram.org/bot{evars['bot_token']}/sendDocument?chat_id={evars['dev_chat_id']}"
  File "/usr/lib/python3.6/os.py", line 669, in __getitem__
    raise KeyError(key) from None
KeyError: 'dev_chat_id'
Error while getting Updates: Conflict: terminated by other getUpdates request; make sure that only one bot instance is running
An uncaught error was raised while handling the error.
Traceback (most recent call last):
  File "/usr/local/lib/python3.6/dist-packages/telegram/ext/dispatcher.py", line 424, in process_update
    self.dispatch_error(None, update)
  File "/usr/local/lib/python3.6/dist-packages/telegram/ext/dispatcher.py", line 674, in dispatch_error
    callback(update, context)
  File "/root/BlockchainBot/base.py", line 56, in error_handler
    url = f"https://api.telegram.org/bot{evars['bot_token']}/sendDocument?chat_id={evars['dev_chat_id']}"
  File "/usr/lib/python3.6/os.py", line 669, in __getitem__
    raise KeyError(key) from None
KeyError: 'dev_chat_id'
Error while getting Updates: Conflict: terminated by other getUpdates request; make sure that only one bot instance is running
An uncaught error was raised while handling the error.
Traceback (most recent call last):
  File "/usr/local/lib/python3.6/dist-packages/telegram/ext/dispatcher.py", line 424, in process_update
    self.dispatch_error(None, update)
  File "/usr/local/lib/python3.6/dist-packages/telegram/ext/dispatcher.py", line 674, in dispatch_error
    callback(update, context)
  File "/root/BlockchainBot/base.py", line 56, in error_handler
    url = f"https://api.telegram.org/bot{evars['bot_token']}/sendDocument?chat_id={evars['dev_chat_id']}"
  File "/usr/lib/python3.6/os.py", line 669, in __getitem__
    raise KeyError(key) from None
KeyError: 'dev_chat_id'
Error while getting Updates: Conflict: terminated by other getUpdates request; make sure that only one bot instance is running
An uncaught error was raised while handling the error.
Traceback (most recent call last):
  File "/usr/local/lib/python3.6/dist-packages/telegram/ext/dispatcher.py", line 424, in process_update
    self.dispatch_error(None, update)
  File "/usr/local/lib/python3.6/dist-packages/telegram/ext/dispatcher.py", line 674, in dispatch_error
    callback(update, context)
  File "/root/BlockchainBot/base.py", line 56, in error_handler
    url = f"https://api.telegram.org/bot{evars['bot_token']}/sendDocument?chat_id={evars['dev_chat_id']}"
  File "/usr/lib/python3.6/os.py", line 669, in __getitem__
    raise KeyError(key) from None
KeyError: 'dev_chat_id'
Error while getting Updates: Conflict: terminated by other getUpdates request; make sure that only one bot instance is running
An uncaught error was raised while handling the error.
Traceback (most recent call last):
  File "/usr/local/lib/python3.6/dist-packages/telegram/ext/dispatcher.py", line 424, in process_update
    self.dispatch_error(None, update)
  File "/usr/local/lib/python3.6/dist-packages/telegram/ext/dispatcher.py", line 674, in dispatch_error
    callback(update, context)
  File "/root/BlockchainBot/base.py", line 56, in error_handler
    url = f"https://api.telegram.org/bot{evars['bot_token']}/sendDocument?chat_id={evars['dev_chat_id']}"
  File "/usr/lib/python3.6/os.py", line 669, in __getitem__
    raise KeyError(key) from None
KeyError: 'dev_chat_id'
Error while getting Updates: Conflict: terminated by other getUpdates request; make sure that only one bot instance is running
An uncaught error was raised while handling the error.
Traceback (most recent call last):
  File "/usr/local/lib/python3.6/dist-packages/telegram/ext/dispatcher.py", line 424, in process_update
    self.dispatch_error(None, update)
  File "/usr/local/lib/python3.6/dist-packages/telegram/ext/dispatcher.py", line 674, in dispatch_error
    callback(update, context)
  File "/root/BlockchainBot/base.py", line 56, in error_handler
    url = f"https://api.telegram.org/bot{evars['bot_token']}/sendDocument?chat_id={evars['dev_chat_id']}"
  File "/usr/lib/python3.6/os.py", line 669, in __getitem__
    raise KeyError(key) from None
KeyError: 'dev_chat_id'
Error while getting Updates: Conflict: terminated by other getUpdates request; make sure that only one bot instance is running
An uncaught error was raised while handling the error.
Traceback (most recent call last):
  File "/usr/local/lib/python3.6/dist-packages/telegram/ext/dispatcher.py", line 424, in process_update
    self.dispatch_error(None, update)
  File "/usr/local/lib/python3.6/dist-packages/telegram/ext/dispatcher.py", line 674, in dispatch_error
    callback(update, context)
  File "/root/BlockchainBot/base.py", line 56, in error_handler
    url = f"https://api.telegram.org/bot{evars['bot_token']}/sendDocument?chat_id={evars['dev_chat_id']}"
  File "/usr/lib/python3.6/os.py", line 669, in __getitem__
    raise KeyError(key) from None
KeyError: 'dev_chat_id'
Error while getting Updates: Conflict: terminated by other getUpdates request; make sure that only one bot instance is running
An uncaught error was raised while handling the error.
Traceback (most recent call last):
  File "/usr/local/lib/python3.6/dist-packages/telegram/ext/dispatcher.py", line 424, in process_update
    self.dispatch_error(None, update)
  File "/usr/local/lib/python3.6/dist-packages/telegram/ext/dispatcher.py", line 674, in dispatch_error
    callback(update, context)
  File "/root/BlockchainBot/base.py", line 56, in error_handler
    url = f"https://api.telegram.org/bot{evars['bot_token']}/sendDocument?chat_id={evars['dev_chat_id']}"
  File "/usr/lib/python3.6/os.py", line 669, in __getitem__
    raise KeyError(key) from None
KeyError: 'dev_chat_id'
Error while getting Updates: Conflict: terminated by other getUpdates request; make sure that only one bot instance is running
An uncaught error was raised while handling the error.
Traceback (most recent call last):
  File "/usr/local/lib/python3.6/dist-packages/telegram/ext/dispatcher.py", line 424, in process_update
    self.dispatch_error(None, update)
  File "/usr/local/lib/python3.6/dist-packages/telegram/ext/dispatcher.py", line 674, in dispatch_error
    callback(update, context)
  File "/root/BlockchainBot/base.py", line 56, in error_handler
    url = f"https://api.telegram.org/bot{evars['bot_token']}/sendDocument?chat_id={evars['dev_chat_id']}"
  File "/usr/lib/python3.6/os.py", line 669, in __getitem__
    raise KeyError(key) from None
KeyError: 'dev_chat_id'
Error while getting Updates: Conflict: terminated by other getUpdates request; make sure that only one bot instance is running
An uncaught error was raised while handling the error.
Traceback (most recent call last):
  File "/usr/local/lib/python3.6/dist-packages/telegram/ext/dispatcher.py", line 424, in process_update
    self.dispatch_error(None, update)
  File "/usr/local/lib/python3.6/dist-packages/telegram/ext/dispatcher.py", line 674, in dispatch_error
    callback(update, context)
  File "/root/BlockchainBot/base.py", line 56, in error_handler
    url = f"https://api.telegram.org/bot{evars['bot_token']}/sendDocument?chat_id={evars['dev_chat_id']}"
  File "/usr/lib/python3.6/os.py", line 669, in __getitem__
    raise KeyError(key) from None
KeyError: 'dev_chat_id'
Error while getting Updates: Conflict: terminated by other getUpdates request; make sure that only one bot instance is running
An uncaught error was raised while handling the error.
Traceback (most recent call last):
  File "/usr/local/lib/python3.6/dist-packages/telegram/ext/dispatcher.py", line 424, in process_update
    self.dispatch_error(None, update)
  File "/usr/local/lib/python3.6/dist-packages/telegram/ext/dispatcher.py", line 674, in dispatch_error
    callback(update, context)
  File "/root/BlockchainBot/base.py", line 56, in error_handler
    url = f"https://api.telegram.org/bot{evars['bot_token']}/sendDocument?chat_id={evars['dev_chat_id']}"
  File "/usr/lib/python3.6/os.py", line 669, in __getitem__
    raise KeyError(key) from None
KeyError: 'dev_chat_id'
Error while getting Updates: Conflict: terminated by other getUpdates request; make sure that only one bot instance is running
An uncaught error was raised while handling the error.
Traceback (most recent call last):
  File "/usr/local/lib/python3.6/dist-packages/telegram/ext/dispatcher.py", line 424, in process_update
    self.dispatch_error(None, update)file:///C:/Users/Alexashka/Downloads/Telegram Desktop/BlockchainBot (14).txt
  File "/usr/local/lib/python3.6/dist-packages/telegram/ext/dispatcher.py", line 674, in dispatch_error
    callback(update, context)
  File "/root/BlockchainBot/base.py", line 56, in error_handler
    url = f"https://api.telegram.org/bot{evars['bot_token']}/sendDocument?chat_id={evars['dev_chat_id']}"
  File "/usr/lib/python3.6/os.py", line 669, in __getitem__
    raise KeyError(key) from None
KeyError: 'dev_chat_id'
/usr/local/lib/python3.6/dist-packages/telegram/ext/conversationhandler.py:280: UserWarning: If 'per_message=False', 'CallbackQueryHandler' will not be tracked for every message.
  "If 'per_message=False', 'CallbackQueryHandler' will not be "
